Workbook

Sheet 3.BICU-NVMC
A1: 序号 | B1: PID | C1: 参数群 | D1: 总字节 | E1: 起始字节Byt | F1: 长度 | G1: 偏移量 | H1: 系数 | I1: 单位 | J1: 特殊释义 | K1: 默认值Dec | L1: 默认值Hex | M1: 默认值Hex | N1: 默认值Hex | O1: 有效最小值 | P1: 有效最大值
A2: 1 | B2: 0xB004 | C2: 电压采集串数群 | D2: 1
C3: BSU单体电压采集总串数 | D3: 1 | E3: 0 | F3: 8 | G3: 0 | H3: 1 | I3: 串 | K3: 16 | M3: ="0x"&DEC2HEX(MOD(K3,256),2) -> 0x10 | N3: ="["&_xlfn.TEXTJOIN(" ",TRUE,L3:M3)&"]" -> [0x10] | O3: 6 | P3: 64
A4: 2 | B4: 0xB009 | C4: 单体电压跳变诊断配置群 | D4: 8
C5: 均衡开启压差 | D5: 1 | E5: 0 | F5: 8 | I5: mV | K5: 20 | M5: ="0x"&DEC2HEX(MOD(K5,256),2) -> 0x14 | O5: 0x00 | P5: 0x03
C6: 均衡关闭温度 | D6: 1 | E6: 1 | F6: 8 | I6: ℃ | J6: -40℃偏移量 | K6: 90 | M6: ="0x"&DEC2HEX(MOD(K6,256),2) -> 0x5A | O6: 1 | P6: 65535
C7: 均衡关闭最高单体电压 | D7: 2 | E7: 2 | F7: 16 | I7: mV | K7: 3630 | L7: ="0x"&DEC2HEX(K7/256,2) -> 0x0E | M7: ="0x"&DEC2HEX(MOD(K7,256),2) -> 0x2E | O7: 100 | P7: 65535
C8: 均衡关闭最低单体电压 | D8: 2 | E8: 4 | F8: 16 | I8: mV | K8: 3100 | L8: ="0x"&DEC2HEX(K8/256,2) -> 0x0C | M8: ="0x"&DEC2HEX(MOD(K8,256),2) -> 0x1C | O8: 10 | P8: 5000
C9: 均衡开关时间 | D9: 2 | E9: 6 | F9: 16 | I9: / | K9: 500 | L9: ="0x"&DEC2HEX(K9/256,2) -> 0x01 | M9: ="0x"&DEC2HEX(MOD(K9,256),2) -> 0xF4 | N9: ="["&_xlfn.TEXTJOIN(" ",TRUE,L5:M9)&"]" -> [0x14 0x5A 0x0E 0x2E 0x0C 0x1C 0x01 0xF4] | O9: 1 | P9: 255
A10: 3 | B10: 0xB00A | C10: 电压温度数群 | D10: 2
C11: BSU单体温度采集总数 | D11: 1 | E11: 0 | F11: 8 | G11: 0 | H11: 1 | I11: 个 | K11: 16 | M11: ="0x"&DEC2HEX(MOD(K11,256),2) -> 0x10 | O11: 6 | P11: 64
C12: BSU采集NTC默认配置表 | D12: 1 | E12: 1 | F12: 8 | G12: 0 | H12: 1 | I12: / | J12: 0x0 10K-预设参数 0x1 100K-预设参数 | K12: 0 | M12: ="0x"&DEC2HEX(MOD(K12,256),2) -> 0x00 | N12: ="["&_xlfn.TEXTJOIN(" ",TRUE,L11:M12)&"]" -> [0x10 0x00]

Sheet 2.BCMU-NVMC
A1: 序号 | B1: 参数PID | C1: 告警类别 | D1: 告警使能 | E1: 成熟/解除确认时间 | F1: 三级阈值 | G1: 解除阈值 | H1: 充/放内部等级 | I1: 二级阈值 | J1: 解除阈值 | K1: 充/放内部等级 | L1: 一级阈值 | M1: 解除阈值 | N1: 充/放内部等级 | O1: 精度&单位 | P1: 备注 | Q1: 一级 | R1: 二级 | S1: 三级 | T1: 串数 | U1: 包数 | V1: HEX
T2: 18 | U2: 1 | V2: bit0 | W2: bit1 | X2: bit2 | Y2: bit3 | Z2: bit4 | AA2: bit5 | AB2: bit6 | AC2: bit7 | AD2: bit8 | AE2: bit9 | AF2: bit10 | AG2: bit11 | AH2: bit12 | AI2: bit13 | AJ2: bit14 | AK2: bit15 | AL2: bit16
A3: 1 | B3: 0xF001 | C3: 单体电压过高 | D3: 3 | E3: 2 | F3: 3550 | G3: 0 | H3: 17 | I3: 3500 | J3: 3455 | K3: 16 | L3: 3455 | M3: 3450 | N3: 16 | O3: 1mv | P3: ≥ | Q3: 1 | R3: 2 | S3: 3 | V3: =DEC2HEX(D3,2) -> 03 | W3: =DEC2HEX(E3,2) -> 02 | X3: =DEC2HEX(F3/256,2) -> 0D | Y3: =DEC2HEX(MOD(F3,256),2) -> DE | Z3: =DEC2HEX(G3/256,2) -> 00 | AA3: =DEC2HEX(MOD(G3,256),2) -> 00 | AB3: =DEC2HEX(H3,2) -> 11 | AC3: =DEC2HEX(I3/256,2) -> 0D | AD3: =DEC2HEX(MOD(I3,256),2) -> AC | AE3: =DEC2HEX(J3/256,2) -> 0D | AF3: =DEC2HEX(MOD(J3,256),2) -> 7F | AG3: =DEC2HEX(K3,2) -> 10 | AH3: =DEC2HEX(L3/256,2) -> 0D | AI3: =DEC2HEX(MOD(L3,256),2) -> 7F | AJ3: =DEC2HEX(M3/256,2) -> 0D | AK3: =DEC2HEX(MOD(M3,256),2) -> 7A | AL3: =DEC2HEX(N3,2) -> 10
A4: 2 | B4: 0xF002 | C4: 单体电压过低 | D4: 3 | E4: 2 | F4: 2850 | G4: 4500 | H4: 14 | I4: 2900 | J4: 2950 | K4: 9 | L4: 2950 | M4: 3000 | N4: 9 | O4: 1mv | P4: ≤ | Q4: 4 | R4: 5 | S4: 6 | V4: =DEC2HEX(D4,2) -> 03 | W4: =DEC2HEX(E4,2) -> 02 | X4: =DEC2HEX(F4/256,2) -> 0B | Y4: =DEC2HEX(MOD(F4,256),2) -> 22 | Z4: =DEC2HEX(G4/256,2) -> 11 | AA4: =DEC2HEX(MOD(G4,256),2) -> 94 | AB4: =DEC2HEX(H4,2) -> 0E | AC4: =DEC2HEX(I4/256,2) -> 0B | AD4: =DEC2HEX(MOD(I4,256),2) -> 54 | AE4: =DEC2HEX(J4/256,2) -> 0B | AF4: =DEC2HEX(MOD(J4,256),2) -> 86 | AG4: =DEC2HEX(K4,2) -> 09 | AH4: =DEC2HEX(L4/256,2) -> 0B | AI4: =DEC2HEX(MOD(L4,256),2) -> 86 | AJ4: =DEC2HEX(M4/256,2) -> 0B | AK4: =DEC2HEX(MOD(M4,256),2) -> B8 | AL4: =DEC2HEX(N4,2) -> 09
A5: 3 | B5: 0xF003 | C5: 单体压差过大 | D5: 3 | E5: 5 | F5: 250 | G5: 0 | H5: 17 | I5: 200 | J5: 195 | K5: 11 | L5: 150 | M5: 145 | N5: 1 | O5: 1mv | P5: ≥ | Q5: 7 | R5: 8 | S5: 9 | V5: =DEC2HEX(D5,2) -> 03 | W5: =DEC2HEX(E5,2) -> 05 | X5: =DEC2HEX(F5/256,2) -> 00 | Y5: =DEC2HEX(MOD(F5,256),2) -> FA | Z5: =DEC2HEX(G5/256,2) -> 00 | AA5: =DEC2HEX(MOD(G5,256),2) -> 00 | AB5: =DEC2HEX(H5,2) -> 11 | AC5: =DEC2HEX(I5/256,2) -> 00 | AD5: =DEC2HEX(MOD(I5,256),2) -> C8 | AE5: =DEC2HEX(J5/256,2) -> 00 | AF5: =DEC2HEX(MOD(J5,256),2) -> C3 | AG5: =DEC2HEX(K5,2) -> 0B | AH5: =DEC2HEX(L5/256,2) -> 00 | AI5: =DEC2HEX(MOD(L5,256),2) -> 96 | AJ5: =DEC2HEX(M5/256,2) -> 00 | AK5: =DEC2HEX(MOD(M5,256),2) -> 91 | AL5: =DEC2HEX(N5,2) -> 01
A6: 4 | B6: 0xF01E | C6: 模块总压过高 | D6: 3 | E6: 2 | F6: =F3*T2/100 -> 639 | G6: =G3*T2/100 -> 0 | H6: 17 | I6: =I3*T2/100 -> 630 | J6: =J3*T2/100 -> 621.9 | K6: 16 | L6: =L3*T2/100 -> 621.9 | M6: =M3*T2/100 -> 621 | N6: 16 | O6: 0.1V | P6: ≥ | Q6: 10 | R6: 11 | S6: 12 | V6: =DEC2HEX(D6,2) -> 03 | W6: =DEC2HEX(E6,2) -> 02 | X6: =DEC2HEX(F6/256,2) -> 02 | Y6: =DEC2HEX(MOD(F6,256),2) -> 7F | Z6: =DEC2HEX(G6/256,2) -> 00 | AA6: =DEC2HEX(MOD(G6,256),2) -> 00 | AB6: =DEC2HEX(H6,2) -> 11 | AC6: =DEC2HEX(I6/256,2) -> 02 | AD6: =DEC2HEX(MOD(I6,256),2) -> 76 | AE6: =DEC2HEX(J6/256,2) -> 02 | AF6: =DEC2HEX(MOD(J6,256),2) -> 6D | AG6: =DEC2HEX(K6,2) -> 10 | AH6: =DEC2HEX(L6/256,2) -> 02 | AI6: =DEC2HEX(MOD(L6,256),2) -> 6D | AJ6: =DEC2HEX(M6/256,2) -> 02 | AK6: =DEC2HEX(MOD(M6,256),2) -> 6D | AL6: =DEC2HEX(N6,2) -> 10
A7: 5 | B7: 0xF01F | C7: 模块总压过低 | D7: 3 | E7: 2 | F7: =F4*T2/100 -> 513 | G7: =G4*T2/100 -> 810 | H7: 14 | I7: =I4*T2/100 -> 522 | J7: =J4*T2/100 -> 531 | K7: 14 | L7: =L4*T2/100 -> 531 | M7: =M4*T2/100 -> 540 | N7: 9 | O7: 0.1V | P7: ≤ | Q7: 13 | R7: 14 | S7: 15 | V7: =DEC2HEX(D7,2) -> 03 | W7: =DEC2HEX(E7,2) -> 02 | X7: =DEC2HEX(F7/256,2) -> 02 | Y7: =DEC2HEX(MOD(F7,256),2) -> 01 | Z7: =DEC2HEX(G7/256,2) -> 03 | AA7: =DEC2HEX(MOD(G7,256),2) -> 2A | AB7: =DEC2HEX(H7,2) -> 0E | AC7: =DEC2HEX(I7/256,2) -> 02 | AD7: =DEC2HEX(MOD(I7,256),2) -> 0A | AE7: =DEC2HEX(J7/256,2) -> 02 | AF7: =DEC2HEX(MOD(J7,256),2) -> 13 | AG7: =DEC2HEX(K7,2) -> 0E | AH7: =DEC2HEX(L7/256,2) -> 02 | AI7: =DEC2HEX(MOD(L7,256),2) -> 13 | AJ7: =DEC2HEX(M7/256,2) -> 02 | AK7: =DEC2HEX(MOD(M7,256),2) -> 1C | AL7: =DEC2HEX(N7,2) -> 09
A8: 6 | B8: 0xF00B | C8: 簇总压过高 | D8: 3 | E8: 2 | F8: =F3*T2*U2/100 -> 639 | G8: =G3*T2*U2/100 -> 0 | H8: 17 | I8: =I3*T2*U2/100 -> 630 | J8: =J3*T2*U2/100 -> 621.9 | K8: 16 | L8: =L3*T2*U2/100 -> 621.9 | M8: =M3*T2*U2/100 -> 621 | N8: 16 | O8: 0.1V | P8: ≥ | Q8: 16 | R8: 17 | S8: 18 | V8: =DEC2HEX(D8,2) -> 03 | W8: =DEC2HEX(E8,2) -> 02 | X8: =DEC2HEX(F8/256,2) -> 02 | Y8: =DEC2HEX(MOD(F8,256),2) -> 7F | Z8: =DEC2HEX(G8/256,2) -> 00 | AA8: =DEC2HEX(MOD(G8,256),2) -> 00 | AB8: =DEC2HEX(H8,2) -> 11 | AC8: =DEC2HEX(I8/256,2) -> 02 | AD8: =DEC2HEX(MOD(I8,256),2) -> 76 | AE8: =DEC2HEX(J8/256,2) -> 02 | AF8: =DEC2HEX(MOD(J8,256),2) -> 6D | AG8: =DEC2HEX(K8,2) -> 10 | AH8: =DEC2HEX(L8/256,2) -> 02 | AI8: =DEC2HEX(MOD(L8,256),2) -> 6D | AJ8: =DEC2HEX(M8/256,2) -> 02 | AK8: =DEC2HEX(MOD(M8,256),2) -> 6D | AL8: =DEC2HEX(N8,2) -> 10
A9: 7 | B9: 0xF00C | C9: 簇总压过低 | D9: 3 | E9: 2 | F9: =F4*T2*U2/100 -> 513 | G9: =G4*T2*U2/100 -> 810 | H9: 14 | I9: =I4*T2*U2/100 -> 522 | J9: =J4*T2*U2/100 -> 531 | K9: 14 | L9: =L4*T2*U2/100 -> 531 | M9: =M4*T2*U2/100 -> 540 | N9: 9 | O9: 0.1V | P9: ≤ | Q9: 19 | R9: 20 | S9: 21 | V9: =DEC2HEX(D9,2) -> 03 | W9: =DEC2HEX(E9,2) -> 02 | X9: =DEC2HEX(F9/256,2) -> 02 | Y9: =DEC2HEX(MOD(F9,256),2) -> 01 | Z9: =DEC2HEX(G9/256,2) -> 03 | AA9: =DEC2HEX(MOD(G9,256),2) -> 2A | AB9: =DEC2HEX(H9,2) -> 0E | AC9: =DEC2HEX(I9/256,2) -> 02 | AD9: =DEC2HEX(MOD(I9,256),2) -> 0A | AE9: =DEC2HEX(J9/256,2) -> 02 | AF9: =DEC2HEX(MOD(J9,256),2) -> 13 | AG9: =DEC2HEX(K9,2) -> 0E | AH9: =DEC2HEX(L9/256,2) -> 02 | AI9: =DEC2HEX(MOD(L9,256),2) -> 13 | AJ9: =DEC2HEX(M9/256,2) -> 02 | AK9: =DEC2HEX(MOD(M9,256),2) -> 1C | AL9: =DEC2HEX(N9,2) -> 09
A10: 8 | B10: 0xF00E | C10: 簇放电电流过大 | D10: 3 | E10: 5 | F10: 30150 | G10: 30000 | H10: 17 | I10: 30100 | J10: 30000 | K10: 9 | L10: 30050 | M10: 30000 | N10: 1 | O10: 0.1A(-30000) | P10: > | Q10: 22 | R10: 23 | S10: 24 | V10: =DEC2HEX(D10,2) -> 03 | W10: =DEC2HEX(E10,2) -> 05 | X10: =DEC2HEX(F10/256,2) -> 75 | Y10: =DEC2HEX(MOD(F10,256),2) -> C6 | Z10: =DEC2HEX(G10/256,2) -> 75 | AA10: =DEC2HEX(MOD(G10,256),2) -> 30 | AB10: =DEC2HEX(H10,2) -> 11 | AC10: =DEC2HEX(I10/256,2) -> 75 | AD10: =DEC2HEX(MOD(I10,256),2) -> 94 | AE10: =DEC2HEX(J10/256,2) -> 75 | AF10: =DEC2HEX(MOD(J10,256),2) -> 30 | AG10: =DEC2HEX(K10,2) -> 09 | AH10: =DEC2HEX(L10/256,2) -> 75 | AI10: =DEC2HEX(MOD(L10,256),2) -> 62 | AJ10: =DEC2HEX(M10/256,2) -> 75 | AK10: =DEC2HEX(MOD(M10,256),2) -> 30 | AL10: =DEC2HEX(N10,2) -> 01
A11: 9 | B11: 0xF00F | C11: 簇充电电流过大 | D11: 3 | E11: 5 | F11: 30150 | G11: 30000 | H11: 17 | I11: 30100 | J11: 30000 | K11: 10 | L11: 30050 | M11: 30000 | N11: 1 | O11: 0.1A(-30000) | P11: > | Q11: 25 | R11: 26 | S11: 27 | V11: =DEC2HEX(D11,2) -> 03 | W11: =DEC2HEX(E11,2) -> 05 | X11: =DEC2HEX(F11/256,2) -> 75 | Y11: =DEC2HEX(MOD(F11,256),2) -> C6 | Z11: =DEC2HEX(G11/256,2) -> 75 | AA11: =DEC2HEX(MOD(G11,256),2) -> 30 | AB11: =DEC2HEX(H11,2) -> 11 | AC11: =DEC2HEX(I11/256,2) -> 75 | AD11: =DEC2HEX(MOD(I11,256),2) -> 94 | AE11: =DEC2HEX(J11/256,2) -> 75 | AF11: =DEC2HEX(MOD(J11,256),2) -> 30 | AG11: =DEC2HEX(K11,2) -> 0A | AH11: =DEC2HEX(L11/256,2) -> 75 | AI11: =DEC2HEX(MOD(L11,256),2) -> 62 | AJ11: =DEC2HEX(M11/256,2) -> 75 | AK11: =DEC2HEX(MOD(M11,256),2) -> 30 | AL11: =DEC2HEX(N11,2) -> 01
A12: 10 | B12: 0xF014 | C12: 高压绝缘故障 | D12: 3 | E12: 20 | F12: 600 | G12: 800 | H12: 17 | I12: 800 | J12: 1000 | K12: 11 | L12: 1000 | M12: 1200 | N12: 1 | O12: 1Ω/V | P12: ≤ | Q12: 28 | R12: 29 | S12: 30 | V12: =DEC2HEX(D12,2) -> 03 | W12: =DEC2HEX(E12,2) -> 14 | X12: =DEC2HEX(F12/256,2) -> 02 | Y12: =DEC2HEX(MOD(F12,256),2) -> 58 | Z12: =DEC2HEX(G12/256,2) -> 03 | AA12: =DEC2HEX(MOD(G12,256),2) -> 20 | AB12: =DEC2HEX(H12,2) -> 11 | AC12: =DEC2HEX(I12/256,2) -> 03 | AD12: =DEC2HEX(MOD(I12,256),2) -> 20 | AE12: =DEC2HEX(J12/256,2) -> 03 | AF12: =DEC2HEX(MOD(J12,256),2) -> E8 | AG12: =DEC2HEX(K12,2) -> 0B | AH12: =DEC2HEX(L12/256,2) -> 03 | AI12: =DEC2HEX(MOD(L12,256),2) -> E8 | AJ12: =DEC2HEX(M12/256,2) -> 04 | AK12: =DEC2HEX(MOD(M12,256),2) -> B0 | AL12: =DEC2HEX(N12,2) -> 01
A13: 11 | B13: 0xF020 | C13: 充电温度高 | D13: 3 | E13: 5 | F13: 100 | G13: 0 | H13: 17 | I13: 95 | J13: 90 | K13: 11 | L13: 90 | M13: 85 | N13: 1 | O13: 1℃(-40) | P13: ≥ | Q13: 31 | R13: 32 | S13: 33 | V13: =DEC2HEX(D13,2) -> 03 | W13: =DEC2HEX(E13,2) -> 05 | X13: =DEC2HEX(F13/256,2) -> 00 | Y13: =DEC2HEX(MOD(F13,256),2) -> 64 | Z13: =DEC2HEX(G13/256,2) -> 00 | AA13: =DEC2HEX(MOD(G13,256),2) -> 00 | AB13: =DEC2HEX(H13,2) -> 11 | AC13: =DEC2HEX(I13/256,2) -> 00 | AD13: =DEC2HEX(MOD(I13,256),2) -> 5F | AE13: =DEC2HEX(J13/256,2) -> 00 | AF13: =DEC2HEX(MOD(J13,256),2) -> 5A | AG13: =DEC2HEX(K13,2) -> 0B | AH13: =DEC2HEX(L13/256,2) -> 00 | AI13: =DEC2HEX(MOD(L13,256),2) -> 5A | AJ13: =DEC2HEX(M13/256,2) -> 00 | AK13: =DEC2HEX(MOD(M13,256),2) -> 55 | AL13: =DEC2HEX(N13,2) -> 01
A14: 12 | B14: 0xF021 | C14: 充电温度低 | D14: 3 | E14: 5 | F14: 42 | G14: 100 | H14: 16 | I14: 44 | J14: 46 | K14: 11 | L14: 46 | M14: 48 | N14: 10 | O14: 1℃(-40) | P14: ≤ | Q14: 34 | R14: 35 | S14: 36 | V14: =DEC2HEX(D14,2) -> 03 | W14: =DEC2HEX(E14,2) -> 05 | X14: =DEC2HEX(F14/256,2) -> 00 | Y14: =DEC2HEX(MOD(F14,256),2) -> 2A | Z14: =DEC2HEX(G14/256,2) -> 00 | AA14: =DEC2HEX(MOD(G14,256),2) -> 64 | AB14: =DEC2HEX(H14,2) -> 10 | AC14: =DEC2HEX(I14/256,2) -> 00 | AD14: =DEC2HEX(MOD(I14,256),2) -> 2C | AE14: =DEC2HEX(J14/256,2) -> 00 | AF14: =DEC2HEX(MOD(J14,256),2) -> 2E | AG14: =DEC2HEX(K14,2) -> 0B | AH14: =DEC2HEX(L14/256,2) -> 00 | AI14: =DEC2HEX(MOD(L14,256),2) -> 2E | AJ14: =DEC2HEX(M14/256,2) -> 00 | AK14: =DEC2HEX(MOD(M14,256),2) -> 30 | AL14: =DEC2HEX(N14,2) -> 0A
A15: 13 | B15: 0xF006 | C15: 放电温度高 | D15: 3 | E15: 5 | F15: 100 | G15: 0 | H15: 17 | I15: 95 | J15: 90 | K15: 11 | L15: 90 | M15: 85 | N15: 1 | O15: 1℃(-40) | P15: ≥ | Q15: 37 | R15: 38 | S15: 39 | V15: =DEC2HEX(D15,2) -> 03 | W15: =DEC2HEX(E15,2) -> 05 | X15: =DEC2HEX(F15/256,2) -> 00 | Y15: =DEC2HEX(MOD(F15,256),2) -> 64 | Z15: =DEC2HEX(G15/256,2) -> 00 | AA15: =DEC2HEX(MOD(G15,256),2) -> 00 | AB15: =DEC2HEX(H15,2) -> 11 | AC15: =DEC2HEX(I15/256,2) -> 00 | AD15: =DEC2HEX(MOD(I15,256),2) -> 5F | AE15: =DEC2HEX(J15/256,2) -> 00 | AF15: =DEC2HEX(MOD(J15,256),2) -> 5A | AG15: =DEC2HEX(K15,2) -> 0B | AH15: =DEC2HEX(L15/256,2) -> 00 | AI15: =DEC2HEX(MOD(L15,256),2) -> 5A | AJ15: =DEC2HEX(M15/256,2) -> 00 | AK15: =DEC2HEX(MOD(M15,256),2) -> 55 | AL15: =DEC2HEX(N15,2) -> 01
A16: 14 | B16: 0xF007 | C16: 放电温度低 | D16: 3 | E16: 5 | F16: 10 | G16: 100 | H16: 17 | I16: 28 | J16: 30 | K16: 11 | L16: 30 | M16: 32 | N16: 9 | O16: 1℃(-40) | P16: ≤ | Q16: 40 | R16: 41 | S16: 42 | V16: =DEC2HEX(D16,2) -> 03 | W16: =DEC2HEX(E16,2) -> 05 | X16: =DEC2HEX(F16/256,2) -> 00 | Y16: =DEC2HEX(MOD(F16,256),2) -> 0A | Z16: =DEC2HEX(G16/256,2) -> 00 | AA16: =DEC2HEX(MOD(G16,256),2) -> 64 | AB16: =DEC2HEX(H16,2) -> 11 | AC16: =DEC2HEX(I16/256,2) -> 00 | AD16: =DEC2HEX(MOD(I16,256),2) -> 1C | AE16: =DEC2HEX(J16/256,2) -> 00 | AF16: =DEC2HEX(MOD(J16,256),2) -> 1E | AG16: =DEC2HEX(K16,2) -> 0B | AH16: =DEC2HEX(L16/256,2) -> 00 | AI16: =DEC2HEX(MOD(L16,256),2) -> 1E | AJ16: =DEC2HEX(M16/256,2) -> 00 | AK16: =DEC2HEX(MOD(M16,256),2) -> 20 | AL16: =DEC2HEX(N16,2) -> 09
A17: 15 | B17: 0xF008 | C17: 温差过大 | D17: 3 | E17: 10 | F17: 55 | G17: 0 | H17: 17 | I17: 50 | J17: 49 | K17: 1 | L17: 48 | M17: 47 | N17: 1 | O17: 1℃(-40) | P17: ≥ | Q17: 43 | R17: 44 | S17: 45 | V17: =DEC2HEX(D17,2) -> 03 | W17: =DEC2HEX(E17,2) -> 0A | X17: =DEC2HEX(F17/256,2) -> 00 | Y17: =DEC2HEX(MOD(F17,256),2) -> 37 | Z17: =DEC2HEX(G17/256,2) -> 00 | AA17: =DEC2HEX(MOD(G17,256),2) -> 00 | AB17: =DEC2HEX(H17,2) -> 11 | AC17: =DEC2HEX(I17/256,2) -> 00 | AD17: =DEC2HEX(MOD(I17,256),2) -> 32 | AE17: =DEC2HEX(J17/256,2) -> 00 | AF17: =DEC2HEX(MOD(J17,256),2) -> 31 | AG17: =DEC2HEX(K17,2) -> 01 | AH17: =DEC2HEX(L17/256,2) -> 00 | AI17: =DEC2HEX(MOD(L17,256),2) -> 30 | AJ17: =DEC2HEX(M17/256,2) -> 00 | AK17: =DEC2HEX(MOD(M17,256),2) -> 2F | AL17: =DEC2HEX(N17,2) -> 01
A18: 16 | B18: 0xF023 | C18: SOC过低 | D18: 3 | E18: 3 | F18: 0 | G18: 5 | H18: 1 | I18: 10 | J18: 10 | K18: 1 | L18: 20 | M18: 20 | N18: 1 | O18: 0.01 | P18: ≤ | Q18: 49 | R18: 50 | S18: 51 | V18: =DEC2HEX(D18,2) -> 03 | W18: =DEC2HEX(E18,2) -> 03 | X18: =DEC2HEX(F18/256,2) -> 00 | Y18: =DEC2HEX(MOD(F18,256),2) -> 00 | Z18: =DEC2HEX(G18/256,2) -> 00 | AA18: =DEC2HEX(MOD(G18,256),2) -> 05 | AB18: =DEC2HEX(H18,2) -> 01 | AC18: =DEC2HEX(I18/256,2) -> 00 | AD18: =DEC2HEX(MOD(I18,256),2) -> 0A | AE18: =DEC2HEX(J18/256,2) -> 00 | AF18: =DEC2HEX(MOD(J18,256),2) -> 0A | AG18: =DEC2HEX(K18,2) -> 01 | AH18: =DEC2HEX(L18/256,2) -> 00 | AI18: =DEC2HEX(MOD(L18,256),2) -> 14 | AJ18: =DEC2HEX(M18/256,2) -> 00 | AK18: =DEC2HEX(MOD(M18,256),2) -> 14 | AL18: =DEC2HEX(N18,2) -> 01
A19: 17 | B19: 0xF024 | C19: SOH过低 | D19: 3 | E19: 3 | F19: 0 | G19: 0 | H19: 0 | I19: 0 | J19: 0 | K19: 0 | L19: 70 | M19: 101 | N19: 1 | O19: 0.01 | P19: ≥ | Q19: 52 | R19: 53 | S19: 54 | V19: =DEC2HEX(D19,2) -> 03 | W19: =DEC2HEX(E19,2) -> 03 | X19: =DEC2HEX(F19/256,2) -> 00 | Y19: =DEC2HEX(MOD(F19,256),2) -> 00 | Z19: =DEC2HEX(G19/256,2) -> 00 | AA19: =DEC2HEX(MOD(G19,256),2) -> 00 | AB19: =DEC2HEX(H19,2) -> 00 | AC19: =DEC2HEX(I19/256,2) -> 00 | AD19: =DEC2HEX(MOD(I19,256),2) -> 00 | AE19: =DEC2HEX(J19/256,2) -> 00 | AF19: =DEC2HEX(MOD(J19,256),2) -> 00 | AG19: =DEC2HEX(K19,2) -> 00 | AH19: =DEC2HEX(L19/256,2) -> 00 | AI19: =DEC2HEX(MOD(L19,256),2) -> 46 | AJ19: =DEC2HEX(M19/256,2) -> 00 | AK19: =DEC2HEX(MOD(M19,256),2) -> 65 | AL19: =DEC2HEX(N19,2) -> 01
A20: 18 | B20: 0xF012 | C20: 供电电压过高 | D20: 1 | E20: 3 | F20: 320 | G20: 260 | H20: 17 | I20: 500 | J20: 500 | K20: 0 | L20: 500 | M20: 500 | N20: 0 | O20: 0.1V | P20: ≤ | Q20: 66 | R20: 67 | S20: 68 | V20: =DEC2HEX(D20,2) -> 01 | W20: =DEC2HEX(E20,2) -> 03 | X20: =DEC2HEX(F20/256,2) -> 01 | Y20: =DEC2HEX(MOD(F20,256),2) -> 40 | Z20: =DEC2HEX(G20/256,2) -> 01 | AA20: =DEC2HEX(MOD(G20,256),2) -> 04 | AB20: =DEC2HEX(H20,2) -> 11 | AC20: =DEC2HEX(I20/256,2) -> 01 | AD20: =DEC2HEX(MOD(I20,256),2) -> F4 | AE20: =DEC2HEX(J20/256,2) -> 01 | AF20: =DEC2HEX(MOD(J20,256),2) -> F4 | AG20: =DEC2HEX(K20,2) -> 00 | AH20: =DEC2HEX(L20/256,2) -> 01 | AI20: =DEC2HEX(MOD(L20,256),2) -> F4 | AJ20: =DEC2HEX(M20/256,2) -> 01 | AK20: =DEC2HEX(MOD(M20,256),2) -> F4 | AL20: =DEC2HEX(N20,2) -> 00
A21: 19 | B21: 0xF013 | C21: 供电电压过低 | D21: 1 | E21: 3 | F21: 90 | G21: 120 | H21: 17 | I21: 0 | J21: 0 | K21: 0 | L21: 0 | M21: 0 | N21: 0 | O21: 0.1V | P21: ≥ | Q21: 69 | R21: 70 | S21: 71 | V21: =DEC2HEX(D21,2) -> 01 | W21: =DEC2HEX(E21,2) -> 03 | X21: =DEC2HEX(F21/256,2) -> 00 | Y21: =DEC2HEX(MOD(F21,256),2) -> 5A | Z21: =DEC2HEX(G21/256,2) -> 00 | AA21: =DEC2HEX(MOD(G21,256),2) -> 78 | AB21: =DEC2HEX(H21,2) -> 11 | AC21: =DEC2HEX(I21/256,2) -> 00 | AD21: =DEC2HEX(MOD(I21,256),2) -> 00 | AE21: =DEC2HEX(J21/256,2) -> 00 | AF21: =DEC2HEX(MOD(J21,256),2) -> 00 | AG21: =DEC2HEX(K21,2) -> 00 | AH21: =DEC2HEX(L21/256,2) -> 00 | AI21: =DEC2HEX(MOD(L21,256),2) -> 00 | AJ21: =DEC2HEX(M21/256,2) -> 00 | AK21: =DEC2HEX(MOD(M21,256),2) -> 00 | AL21: =DEC2HEX(N21,2) -> 00
A22: 20 | B22: 0xF010 | C22: 环境温度过高 | D22: 2 | E22: 5 | F22: 100 | G22: 0 | H22: 17 | I22: 95 | J22: 85 | K22: 10 | L22: 85 | M22: 82 | N22: 1 | O22: 1℃(-40) | P22: ≥ | Q22: 74 | R22: 75 | S22: 76 | V22: =DEC2HEX(D22,2) -> 02 | W22: =DEC2HEX(E22,2) -> 05 | X22: =DEC2HEX(F22/256,2) -> 00 | Y22: =DEC2HEX(MOD(F22,256),2) -> 64 | Z22: =DEC2HEX(G22/256,2) -> 00 | AA22: =DEC2HEX(MOD(G22,256),2) -> 00 | AB22: =DEC2HEX(H22,2) -> 11 | AC22: =DEC2HEX(I22/256,2) -> 00 | AD22: =DEC2HEX(MOD(I22,256),2) -> 5F | AE22: =DEC2HEX(J22/256,2) -> 00 | AF22: =DEC2HEX(MOD(J22,256),2) -> 55 | AG22: =DEC2HEX(K22,2) -> 0A | AH22: =DEC2HEX(L22/256,2) -> 00 | AI22: =DEC2HEX(MOD(L22,256),2) -> 55 | AJ22: =DEC2HEX(M22/256,2) -> 00 | AK22: =DEC2HEX(MOD(M22,256),2) -> 52 | AL22: =DEC2HEX(N22,2) -> 01
A23: 21 | B23: 0xF011 | C23: 环境温度过低 | D23: 2 | E23: 5 | F23: 10 | G23: 30 | H23: 17 | I23: 30 | J23: 35 | K23: 11 | L23: 0 | M23: 0 | N23: 0 | O23: 1℃(-40) | P23: ≤ | Q23: 77 | R23: 78 | S23: 79 | V23: =DEC2HEX(D23,2) -> 02 | W23: =DEC2HEX(E23,2) -> 05 | X23: =DEC2HEX(F23/256,2) -> 00 | Y23: =DEC2HEX(MOD(F23,256),2) -> 0A | Z23: =DEC2HEX(G23/256,2) -> 00 | AA23: =DEC2HEX(MOD(G23,256),2) -> 1E | AB23: =DEC2HEX(H23,2) -> 11 | AC23: =DEC2HEX(I23/256,2) -> 00 | AD23: =DEC2HEX(MOD(I23,256),2) -> 1E | AE23: =DEC2HEX(J23/256,2) -> 00 | AF23: =DEC2HEX(MOD(J23,256),2) -> 23 | AG23: =DEC2HEX(K23,2) -> 0B | AH23: =DEC2HEX(L23/256,2) -> 00 | AI23: =DEC2HEX(MOD(L23,256),2) -> 00 | AJ23: =DEC2HEX(M23/256,2) -> 00 | AK23: =DEC2HEX(MOD(M23,256),2) -> 00 | AL23: =DEC2HEX(N23,2) -> 00
A24: 22 | B24: 0xF019 | C24: S板过高温(单体) | D24: 1 | E24: 5 | F24: 105 | G24: 0 | H24: 17 | I24: 0 | J24: 0 | K24: 0 | L24: 0 | M24: 0 | N24: 0 | O24: 1℃(-40) | P24: ≤ | S24: 91 | V24: =DEC2HEX(D24,2) -> 01 | W24: =DEC2HEX(E24,2) -> 05 | X24: =DEC2HEX(F24/256,2) -> 00 | Y24: =DEC2HEX(MOD(F24,256),2) -> 69 | Z24: =DEC2HEX(G24/256,2) -> 00 | AA24: =DEC2HEX(MOD(G24,256),2) -> 00 | AB24: =DEC2HEX(H24,2) -> 11 | AC24: =DEC2HEX(I24/256,2) -> 00 | AD24: =DEC2HEX(MOD(I24,256),2) -> 00 | AE24: =DEC2HEX(J24/256,2) -> 00 | AF24: =DEC2HEX(MOD(J24,256),2) -> 00 | AG24: =DEC2HEX(K24,2) -> 00 | AH24: =DEC2HEX(L24/256,2) -> 00 | AI24: =DEC2HEX(MOD(L24,256),2) -> 00 | AJ24: =DEC2HEX(M24/256,2) -> 00 | AK24: =DEC2HEX(MOD(M24,256),2) -> 00 | AL24: =DEC2HEX(N24,2) -> 00
A25: 23 | B25: 0xF01A | C25: S板过高温(环境) | D25: 1 | E25: 5 | F25: 105 | G25: 0 | H25: 17 | I25: 0 | J25: 0 | K25: 0 | L25: 0 | M25: 0 | N25: 0 | O25: 1℃(-40) | P25: ≤ | S25: 92 | V25: =DEC2HEX(D25,2) -> 01 | W25: =DEC2HEX(E25,2) -> 05 | X25: =DEC2HEX(F25/256,2) -> 00 | Y25: =DEC2HEX(MOD(F25,256),2) -> 69 | Z25: =DEC2HEX(G25/256,2) -> 00 | AA25: =DEC2HEX(MOD(G25,256),2) -> 00 | AB25: =DEC2HEX(H25,2) -> 11 | AC25: =DEC2HEX(I25/256,2) -> 00 | AD25: =DEC2HEX(MOD(I25,256),2) -> 00 | AE25: =DEC2HEX(J25/256,2) -> 00 | AF25: =DEC2HEX(MOD(J25,256),2) -> 00 | AG25: =DEC2HEX(K25,2) -> 00 | AH25: =DEC2HEX(L25/256,2) -> 00 | AI25: =DEC2HEX(MOD(L25,256),2) -> 00 | AJ25: =DEC2HEX(M25/256,2) -> 00 | AK25: =DEC2HEX(MOD(M25,256),2) -> 00 | AL25: =DEC2HEX(N25,2) -> 00
A26: 24 | B26: 0xF01B | C26: S板充电插座过温 | D26: 3 | E26: 3 | F26: 200 | G26: 200 | H26: 0 | I26: 140 | J26: 0 | K26: 17 | L26: 135 | M26: 130 | N26: 10 | O26: 1℃(-40) | P26: ≥ | Q26: 93 | R26: 94 | V26: =DEC2HEX(D26,2) -> 03 | W26: =DEC2HEX(E26,2) -> 03 | X26: =DEC2HEX(F26/256,2) -> 00 | Y26: =DEC2HEX(MOD(F26,256),2) -> C8 | Z26: =DEC2HEX(G26/256,2) -> 00 | AA26: =DEC2HEX(MOD(G26,256),2) -> C8 | AB26: =DEC2HEX(H26,2) -> 00 | AC26: =DEC2HEX(I26/256,2) -> 00 | AD26: =DEC2HEX(MOD(I26,256),2) -> 8C | AE26: =DEC2HEX(J26/256,2) -> 00 | AF26: =DEC2HEX(MOD(J26,256),2) -> 00 | AG26: =DEC2HEX(K26,2) -> 11 | AH26: =DEC2HEX(L26/256,2) -> 00 | AI26: =DEC2HEX(MOD(L26,256),2) -> 87 | AJ26: =DEC2HEX(M26/256,2) -> 00 | AK26: =DEC2HEX(MOD(M26,256),2) -> 82 | AL26: =DEC2HEX(N26,2) -> 0A
A27: 25 | B27: 0xF01C | C27: 环流过大 | D27: 1 | E27: 3 | F27: 100 | G27: 0 | H27: 17 | I27: 0 | J27: 0 | K27: 0 | L27: 0 | M27: 0 | N27: 0 | O27: 0.1A | P27: ≥ | S27: 96 | V27: =DEC2HEX(D27,2) -> 01 | W27: =DEC2HEX(E27,2) -> 03 | X27: =DEC2HEX(F27/256,2) -> 00 | Y27: =DEC2HEX(MOD(F27,256),2) -> 64 | Z27: =DEC2HEX(G27/256,2) -> 00 | AA27: =DEC2HEX(MOD(G27,256),2) -> 00 | AB27: =DEC2HEX(H27,2) -> 11 | AC27: =DEC2HEX(I27/256,2) -> 00 | AD27: =DEC2HEX(MOD(I27,256),2) -> 00 | AE27: =DEC2HEX(J27/256,2) -> 00 | AF27: =DEC2HEX(MOD(J27,256),2) -> 00 | AG27: =DEC2HEX(K27,2) -> 00 | AH27: =DEC2HEX(L27/256,2) -> 00 | AI27: =DEC2HEX(MOD(L27,256),2) -> 00 | AJ27: =DEC2HEX(M27/256,2) -> 00 | AK27: =DEC2HEX(MOD(M27,256),2) -> 00 | AL27: =DEC2HEX(N27,2) -> 00
A28: 手动写 | B28: 自动算 | C28: 十进制
A30: =ROW()-29 -> 1 | B30: =B3 -> 0xF001 | C30: ="[0x"&_xlfn.TEXTJOIN(",0x",TRUE,V3:AL3)&"]" -> [0x03,0x02,0x0D,0xDE,0x00,0x00,0x11,0x0D,0xAC,0x0D,0x7F,0x10,0x0D,0x7F,0x0D,0x7A,0x10]
A31: =ROW()-29 -> 2 | B31: =B4 -> 0xF002 | C31: ="[0x"&_xlfn.TEXTJOIN(",0x",TRUE,V4:AL4)&"]" -> [0x03,0x02,0x0B,0x22,0x11,0x94,0x0E,0x0B,0x54,0x0B,0x86,0x09,0x0B,0x86,0x0B,0xB8,0x09]
A32: =ROW()-29 -> 3 | B32: =B5 -> 0xF003 | C32: ="[0x"&_xlfn.TEXTJOIN(",0x",TRUE,V5:AL5)&"]" -> [0x03,0x05,0x00,0xFA,0x00,0x00,0x11,0x00,0xC8,0x00,0xC3,0x0B,0x00,0x96,0x00,0x91,0x01]
A33: =ROW()-29 -> 4 | B33: =B6 -> 0xF01E | C33: ="[0x"&_xlfn.TEXTJOIN(",0x",TRUE,V6:AL6)&"]" -> [0x03,0x02,0x02,0x7F,0x00,0x00,0x11,0x02,0x76,0x02,0x6D,0x10,0x02,0x6D,0x02,0x6D,0x10]
A34: =ROW()-29 -> 5 | B34: =B7 -> 0xF01F | C34: ="[0x"&_xlfn.TEXTJOIN(",0x",TRUE,V7:AL7)&"]" -> [0x03,0x02,0x02,0x01,0x03,0x2A,0x0E,0x02,0x0A,0x02,0x13,0x0E,0x02,0x13,0x02,0x1C,0x09]
A35: =ROW()-29 -> 6 | B35: =B8 -> 0xF00B | C35: ="[0x"&_xlfn.TEXTJOIN(",0x",TRUE,V8:AL8)&"]" -> [0x03,0x02,0x02,0x7F,0x00,0x00,0x11,0x02,0x76,0x02,0x6D,0x10,0x02,0x6D,0x02,0x6D,0x10]
A36: =ROW()-29 -> 7 | B36: =B9 -> 0xF00C | C36: ="[0x"&_xlfn.TEXTJOIN(",0x",TRUE,V9:AL9)&"]" -> [0x03,0x02,0x02,0x01,0x03,0x2A,0x0E,0x02,0x0A,0x02,0x13,0x0E,0x02,0x13,0x02,0x1C,0x09]
A37: =ROW()-29 -> 8 | B37: =B10 -> 0xF00E | C37: ="[0x"&_xlfn.TEXTJOIN(",0x",TRUE,V10:AL10)&"]" -> [0x03,0x05,0x75,0xC6,0x75,0x30,0x11,0x75,0x94,0x75,0x30,0x09,0x75,0x62,0x75,0x30,0x01]
A38: =ROW()-29 -> 9 | B38: =B11 -> 0xF00F | C38: ="[0x"&_xlfn.TEXTJOIN(",0x",TRUE,V11:AL11)&"]" -> [0x03,0x05,0x75,0xC6,0x75,0x30,0x11,0x75,0x94,0x75,0x30,0x0A,0x75,0x62,0x75,0x30,0x01]
A39: =ROW()-29 -> 10 | B39: =B12 -> 0xF014 | C39: ="[0x"&_xlfn.TEXTJOIN(",0x",TRUE,V12:AL12)&"]" -> [0x03,0x14,0x02,0x58,0x03,0x20,0x11,0x03,0x20,0x03,0xE8,0x0B,0x03,0xE8,0x04,0xB0,0x01]
A40: =ROW()-29 -> 11 | B40: =B13 -> 0xF020 | C40: ="[0x"&_xlfn.TEXTJOIN(",0x",TRUE,V13:AL13)&"]" -> [0x03,0x05,0x00,0x64,0x00,0x00,0x11,0x00,0x5F,0x00,0x5A,0x0B,0x00,0x5A,0x00,0x55,0x01]
A41: =ROW()-29 -> 12 | B41: =B14 -> 0xF021 | C41: ="[0x"&_xlfn.TEXTJOIN(",0x",TRUE,V14:AL14)&"]" -> [0x03,0x05,0x00,0x2A,0x00,0x64,0x10,0x00,0x2C,0x00,0x2E,0x0B,0x00,0x2E,0x00,0x30,0x0A]
...

Sheet 2.按PID大小排序
A1: ='2.BCMU-NVMC'!A1 -> 序号 | B1: ='2.BCMU-NVMC'!B1 -> 参数PID | C1: ='2.BCMU-NVMC'!C1 -> 告警类别 | D1: ='2.BCMU-NVMC'!D1 -> 告警使能 | E1: ='2.BCMU-NVMC'!E1 -> 成熟/解除确认时间 | F1: ='2.BCMU-NVMC'!F1 -> 三级阈值 | G1: ='2.BCMU-NVMC'!G1 -> 解除阈值 | H1: ='2.BCMU-NVMC'!H1 -> 充/放内部等级 | ... U1: ='2.BCMU-NVMC'!U1 -> 包数 | V1: HEX
T2: ='2.BCMU-NVMC'!T2 -> 18 | U2: ='2.BCMU-NVMC'!U2 -> 1 | V2: bit0 | W2: bit1 | X2: bit2 | Y2: bit3 | Z2: bit4 | AA2: bit5 | AB2: bit6 | AC2: bit7 | AD2: bit8 | AE2: bit9 | AF2: bit10 | AG2: bit11 | AH2: bit12 | AI2: bit13 | AJ2: bit14 | AK2: bit15 | AL2: bit16
A3: ='2.BCMU-NVMC'!A3 -> 1 | B3: ='2.BCMU-NVMC'!B3 -> 0xF001 | C3: ='2.BCMU-NVMC'!C3 -> 单体电压过高 | D3: ='2.BCMU-NVMC'!D3 -> 3 | E3: ='2.BCMU-NVMC'!E3 -> 2 | F3: ='2.BCMU-NVMC'!F3 -> 3550 | G3: ='2.BCMU-NVMC'!G3 -> 0 | H3: ='2.BCMU-NVMC'!H3 -> 17 | ... S3: ='2.BCMU-NVMC'!S3 -> 3 | V3: =DEC2HEX(D3,2) -> 03 | W3: =DEC2HEX(E3,2) -> 02 | X3: =DEC2HEX(F3/256,2) -> 0D | Y3: =DEC2HEX(MOD(F3,256),2) -> DE | Z3: =DEC2HEX(G3/256,2) -> 00 | AA3: =DEC2HEX(MOD(G3,256),2) -> 00 | AB3: =DEC2HEX(H3,2) -> 11 | AC3: =DEC2HEX(I3/256,2) -> 0D | AD3: =DEC2HEX(MOD(I3,256),2) -> AC | AE3: =DEC2HEX(J3/256,2) -> 0D | AF3: =DEC2HEX(MOD(J3,256),2) -> 7F | AG3: =DEC2HEX(K3,2) -> 10 | AH3: =DEC2HEX(L3/256,2) -> 0D | AI3: =DEC2HEX(MOD(L3,256),2) -> 7F | AJ3: =DEC2HEX(M3/256,2) -> 0D | AK3: =DEC2HEX(MOD(M3,256),2) -> 7A | AL3: =DEC2HEX(N3,2) -> 10
A4: ='2.BCMU-NVMC'!A4 -> 2 | B4: ='2.BCMU-NVMC'!B4 -> 0xF002 | C4: ='2.BCMU-NVMC'!C4 -> 单体电压过低 | D4: ='2.BCMU-NVMC'!D4 -> 3 | E4: ='2.BCMU-NVMC'!E4 -> 2 | F4: ='2.BCMU-NVMC'!F4 -> 2850 | G4: ='2.BCMU-NVMC'!G4 -> 4500 | H4: ='2.BCMU-NVMC'!H4 -> 14 | ... S4: ='2.BCMU-NVMC'!S4 -> 6 | V4: =DEC2HEX(D4,2) -> 03 | W4: =DEC2HEX(E4,2) -> 02 | X4: =DEC2HEX(F4/256,2) -> 0B | Y4: =DEC2HEX(MOD(F4,256),2) -> 22 | Z4: =DEC2HEX(G4/256,2) -> 11 | AA4: =DEC2HEX(MOD(G4,256),2) -> 94 | AB4: =DEC2HEX(H4,2) -> 0E | AC4: =DEC2HEX(I4/256,2) -> 0B | AD4: =DEC2HEX(MOD(I4,256),2) -> 54 | AE4: =DEC2HEX(J4/256,2) -> 0B | AF4: =DEC2HEX(MOD(J4,256),2) -> 86 | AG4: =DEC2HEX(K4,2) -> 09 | AH4: =DEC2HEX(L4/256,2) -> 0B | AI4: =DEC2HEX(MOD(L4,256),2) -> 86 | AJ4: =DEC2HEX(M4/256,2) -> 0B | AK4: =DEC2HEX(MOD(M4,256),2) -> B8 | AL4: =DEC2HEX(N4,2) -> 09
A5: ='2.BCMU-NVMC'!A5 -> 3 | B5: ='2.BCMU-NVMC'!B5 -> 0xF003 | C5: ='2.BCMU-NVMC'!C5 -> 单体压差过大 | D5: ='2.BCMU-NVMC'!D5 -> 3 | E5: ='2.BCMU-NVMC'!E5 -> 5 | F5: ='2.BCMU-NVMC'!F5 -> 250 | G5: ='2.BCMU-NVMC'!G5 -> 0 | H5: ='2.BCMU-NVMC'!H5 -> 17 | ... S5: ='2.BCMU-NVMC'!S5 -> 9 | V5: =DEC2HEX(D5,2) -> 03 | W5: =DEC2HEX(E5,2) -> 05 | X5: =DEC2HEX(F5/256,2) -> 00 | Y5: =DEC2HEX(MOD(F5,256),2) -> FA | Z5: =DEC2HEX(G5/256,2) -> 00 | AA5: =DEC2HEX(MOD(G5,256),2) -> 00 | AB5: =DEC2HEX(H5,2) -> 11 | AC5: =DEC2HEX(I5/256,2) -> 00 | AD5: =DEC2HEX(MOD(I5,256),2) -> C8 | AE5: =DEC2HEX(J5/256,2) -> 00 | AF5: =DEC2HEX(MOD(J5,256),2) -> C3 | AG5: =DEC2HEX(K5,2) -> 0B | AH5: =DEC2HEX(L5/256,2) -> 00 | AI5: =DEC2HEX(MOD(L5,256),2) -> 96 | AJ5: =DEC2HEX(M5/256,2) -> 00 | AK5: =DEC2HEX(MOD(M5,256),2) -> 91 | AL5: =DEC2HEX(N5,2) -> 01
A6: ='2.BCMU-NVMC'!A15 -> 13 | B6: ='2.BCMU-NVMC'!B15 -> 0xF006 | C6: ='2.BCMU-NVMC'!C15 -> 放电温度高 | D6: ='2.BCMU-NVMC'!D15 -> 3 | E6: ='2.BCMU-NVMC'!E15 -> 5 | F6: ='2.BCMU-NVMC'!F15 -> 100 | G6: ='2.BCMU-NVMC'!G15 -> 0 | H6: ='2.BCMU-NVMC'!H15 -> 17 | ... S6: ='2.BCMU-NVMC'!S15 -> 39 | V6: =DEC2HEX(D6,2) -> 03 | W6: =DEC2HEX(E6,2) -> 05 | X6: =DEC2HEX(F6/256,2) -> 00 | Y6: =DEC2HEX(MOD(F6,256),2) -> 64 | Z6: =DEC2HEX(G6/256,2) -> 00 | AA6: =DEC2HEX(MOD(G6,256),2) -> 00 | AB6: =DEC2HEX(H6,2) -> 11 | AC6: =DEC2HEX(I6/256,2) -> 00 | AD6: =DEC2HEX(MOD(I6,256),2) -> 5F | AE6: =DEC2HEX(J6/256,2) -> 00 | AF6: =DEC2HEX(MOD(J6,256),2) -> 5A | AG6: =DEC2HEX(K6,2) -> 0B | AH6: =DEC2HEX(L6/256,2) -> 00 | AI6: =DEC2HEX(MOD(L6,256),2) -> 5A | AJ6: =DEC2HEX(M6/256,2) -> 00 | AK6: =DEC2HEX(MOD(M6,256),2) -> 55 | AL6: =DEC2HEX(N6,2) -> 01
A7: ='2.BCMU-NVMC'!A16 -> 14 | B7: ='2.BCMU-NVMC'!B16 -> 0xF007 | C7: ='2.BCMU-NVMC'!C16 -> 放电温度低 | D7: ='2.BCMU-NVMC'!D16 -> 3 | E7: ='2.BCMU-NVMC'!E16 -> 5 | F7: ='2.BCMU-NVMC'!F16 -> 10 | G7: ='2.BCMU-NVMC'!G16 -> 100 | H7: ='2.BCMU-NVMC'!H16 -> 17 | ... S7: ='2.BCMU-NVMC'!S16 -> 42 | V7: =DEC2HEX(D7,2) -> 03 | W7: =DEC2HEX(E7,2) -> 05 | X7: =DEC2HEX(F7/256,2) -> 00 | Y7: =DEC2HEX(MOD(F7,256),2) -> 0A | Z7: =DEC2HEX(G7/256,2) -> 00 | AA7: =DEC2HEX(MOD(G7,256),2) -> 64 | AB7: =DEC2HEX(H7,2) -> 11 | AC7: =DEC2HEX(I7/256,2) -> 00 | AD7: =DEC2HEX(MOD(I7,256),2) -> 1C | AE7: =DEC2HEX(J7/256,2) -> 00 | AF7: =DEC2HEX(MOD(J7,256),2) -> 1E | AG7: =DEC2HEX(K7,2) -> 0B | AH7: =DEC2HEX(L7/256,2) -> 00 | AI7: =DEC2HEX(MOD(L7,256),2) -> 1E | AJ7: =DEC2HEX(M7/256,2) -> 00 | AK7: =DEC2HEX(MOD(M7,256),2) -> 20 | AL7: =DEC2HEX(N7,2) -> 09
A8: ='2.BCMU-NVMC'!A17 -> 15 | B8: ='2.BCMU-NVMC'!B17 -> 0xF008 | C8: ='2.BCMU-NVMC'!C17 -> 温差过大 | D8: ='2.BCMU-NVMC'!D17 -> 3 | E8: ='2.BCMU-NVMC'!E17 -> 10 | F8: ='2.BCMU-NVMC'!F17 -> 55 | G8: ='2.BCMU-NVMC'!G17 -> 0 | H8: ='2.BCMU-NVMC'!H17 -> 17 | ... S8: ='2.BCMU-NVMC'!S17 -> 45 | V8: =DEC2HEX(D8,2) -> 03 | W8: =DEC2HEX(E8,2) -> 0A | X8: =DEC2HEX(F8/256,2) -> 00 | Y8: =DEC2HEX(MOD(F8,256),2) -> 37 | Z8: =DEC2HEX(G8/256,2) -> 00 | AA8: =DEC2HEX(MOD(G8,256),2) -> 00 | AB8: =DEC2HEX(H8,2) -> 11 | AC8: =DEC2HEX(I8/256,2) -> 00 | AD8: =DEC2HEX(MOD(I8,256),2) -> 32 | AE8: =DEC2HEX(J8/256,2) -> 00 | AF8: =DEC2HEX(MOD(J8,256),2) -> 31 | AG8: =DEC2HEX(K8,2) -> 01 | AH8: =DEC2HEX(L8/256,2) -> 00 | AI8: =DEC2HEX(MOD(L8,256),2) -> 30 | AJ8: =DEC2HEX(M8/256,2) -> 00 | AK8: =DEC2HEX(MOD(M8,256),2) -> 2F | AL8: =DEC2HEX(N8,2) -> 01
A9: ='2.BCMU-NVMC'!A8 -> 6 | B9: ='2.BCMU-NVMC'!B8 -> 0xF00B | C9: ='2.BCMU-NVMC'!C8 -> 簇总压过高 | D9: ='2.BCMU-NVMC'!D8 -> 3 | E9: ='2.BCMU-NVMC'!E8 -> 2 | F9: ='2.BCMU-NVMC'!F8 -> 639 | G9: ='2.BCMU-NVMC'!G8 -> 0 | H9: ='2.BCMU-NVMC'!H8 -> 17 | ... S9: ='2.BCMU-NVMC'!S8 -> 18 | V9: =DEC2HEX(D9,2) -> 03 | W9: =DEC2HEX(E9,2) -> 02 | X9: =DEC2HEX(F9/256,2) -> 02 | Y9: =DEC2HEX(MOD(F9,256),2) -> 7F | Z9: =DEC2HEX(G9/256,2) -> 00 | AA9: =DEC2HEX(MOD(G9,256),2) -> 00 | AB9: =DEC2HEX(H9,2) -> 11 | AC9: =DEC2HEX(I9/256,2) -> 02 | AD9: =DEC2HEX(MOD(I9,256),2) -> 76 | AE9: =DEC2HEX(J9/256,2) -> 02 | AF9: =DEC2HEX(MOD(J9,256),2) -> 6D | AG9: =DEC2HEX(K9,2) -> 10 | AH9: =DEC2HEX(L9/256,2) -> 02 | AI9: =DEC2HEX(MOD(L9,256),2) -> 6D | AJ9: =DEC2HEX(M9/256,2) -> 02 | AK9: =DEC2HEX(MOD(M9,256),2) -> 6D | AL9: =DEC2HEX(N9,2) -> 10
A10: ='2.BCMU-NVMC'!A9 -> 7 | B10: ='2.BCMU-NVMC'!B9 -> 0xF00C | C10: ='2.BCMU-NVMC'!C9 -> 簇总压过低 | D10: ='2.BCMU-NVMC'!D9 -> 3 | E10: ='2.BCMU-NVMC'!E9 -> 2 | F10: ='2.BCMU-NVMC'!F9 -> 513 | G10: ='2.BCMU-NVMC'!G9 -> 810 | H10: ='2.BCMU-NVMC'!H9 -> 14 | ... S10: ='2.BCMU-NVMC'!S9 -> 21 | V10: =DEC2HEX(D10,2) -> 03 | W10: =DEC2HEX(E10,2) -> 02 | X10: =DEC2HEX(F10/256,2) -> 02 | Y10: =DEC2HEX(MOD(F10,256),2) -> 01 | Z10: =DEC2HEX(G10/256,2) -> 03 | AA10: =DEC2HEX(MOD(G10,256),2) -> 2A | AB10: =DEC2HEX(H10,2) -> 0E | AC10: =DEC2HEX(I10/256,2) -> 02 | AD10: =DEC2HEX(MOD(I10,256),2) -> 0A | AE10: =DEC2HEX(J10/256,2) -> 02 | AF10: =DEC2HEX(MOD(J10,256),2) -> 13 | AG10: =DEC2HEX(K10,2) -> 0E | AH10: =DEC2HEX(L10/256,2) -> 02 | AI10: =DEC2HEX(MOD(L10,256),2) -> 13 | AJ10: =DEC2HEX(M10/256,2) -> 02 | AK10: =DEC2HEX(MOD(M10,256),2) -> 1C | AL10: =DEC2HEX(N10,2) -> 09
A11: ='2.BCMU-NVMC'!A10 -> 8 | B11: ='2.BCMU-NVMC'!B10 -> 0xF00E | C11: ='2.BCMU-NVMC'!C10 -> 簇放电电流过大 | D11: ='2.BCMU-NVMC'!D10 -> 3 | E11: ='2.BCMU-NVMC'!E10 -> 5 | F11: ='2.BCMU-NVMC'!F10 -> 30150 | G11: ='2.BCMU-NVMC'!G10 -> 30000 | H11: ='2.BCMU-NVMC'!H10 -> 17 | ... S11: ='2.BCMU-NVMC'!S10 -> 24 | V11: =DEC2HEX(D11,2) -> 03 | W11: =DEC2HEX(E11,2) -> 05 | X11: =DEC2HEX(F11/256,2) -> 75 | Y11: =DEC2HEX(MOD(F11,256),2) -> C6 | Z11: =DEC2HEX(G11/256,2) -> 75 | AA11: =DEC2HEX(MOD(G11,256),2) -> 30 | AB11: =DEC2HEX(H11,2) -> 11 | AC11: =DEC2HEX(I11/256,2) -> 75 | AD11: =DEC2HEX(MOD(I11,256),2) -> 94 | AE11: =DEC2HEX(J11/256,2) -> 75 | AF11: =DEC2HEX(MOD(J11,256),2) -> 30 | AG11: =DEC2HEX(K11,2) -> 09 | AH11: =DEC2HEX(L11/256,2) -> 75 | AI11: =DEC2HEX(MOD(L11,256),2) -> 62 | AJ11: =DEC2HEX(M11/256,2) -> 75 | AK11: =DEC2HEX(MOD(M11,256),2) -> 30 | AL11: =DEC2HEX(N11,2) -> 01
A12: ='2.BCMU-NVMC'!A11 -> 9 | B12: ='2.BCMU-NVMC'!B11 -> 0xF00F | C12: ='2.BCMU-NVMC'!C11 -> 簇充电电流过大 | D12: ='2.BCMU-NVMC'!D11 -> 3 | E12: ='2.BCMU-NVMC'!E11 -> 5 | F12: ='2.BCMU-NVMC'!F11 -> 30150 | G12: ='2.BCMU-NVMC'!G11 -> 30000 | H12: ='2.BCMU-NVMC'!H11 -> 17 | ... S12: ='2.BCMU-NVMC'!S11 -> 27 | V12: =DEC2HEX(D12,2) -> 03 | W12: =DEC2HEX(E12,2) -> 05 | X12: =DEC2HEX(F12/256,2) -> 75 | Y12: =DEC2HEX(MOD(F12,256),2) -> C6 | Z12: =DEC2HEX(G12/256,2) -> 75 | AA12: =DEC2HEX(MOD(G12,256),2) -> 30 | AB12: =DEC2HEX(H12,2) -> 11 | AC12: =DEC2HEX(I12/256,2) -> 75 | AD12: =DEC2HEX(MOD(I12,256),2) -> 94 | AE12: =DEC2HEX(J12/256,2) -> 75 | AF12: =DEC2HEX(MOD(J12,256),2) -> 30 | AG12: =DEC2HEX(K12,2) -> 0A | AH12: =DEC2HEX(L12/256,2) -> 75 | AI12: =DEC2HEX(MOD(L12,256),2) -> 62 | AJ12: =DEC2HEX(M12/256,2) -> 75 | AK12: =DEC2HEX(MOD(M12,256),2) -> 30 | AL12: =DEC2HEX(N12,2) -> 01
A13: ='2.BCMU-NVMC'!A22 -> 20 | B13: ='2.BCMU-NVMC'!B22 -> 0xF010 | C13: ='2.BCMU-NVMC'!C22 -> 环境温度过高 | D13: ='2.BCMU-NVMC'!D22 -> 2 | E13: ='2.BCMU-NVMC'!E22 -> 5 | F13: ='2.BCMU-NVMC'!F22 -> 100 | G13: ='2.BCMU-NVMC'!G22 -> 0 | H13: ='2.BCMU-NVMC'!H22 -> 17 | ... S13: ='2.BCMU-NVMC'!S22 -> 76 | V13: =DEC2HEX(D13,2) -> 02 | W13: =DEC2HEX(E13,2) -> 05 | X13: =DEC2HEX(F13/256,2) -> 00 | Y13: =DEC2HEX(MOD(F13,256),2) -> 64 | Z13: =DEC2HEX(G13/256,2) -> 00 | AA13: =DEC2HEX(MOD(G13,256),2) -> 00 | AB13: =DEC2HEX(H13,2) -> 11 | AC13: =DEC2HEX(I13/256,2) -> 00 | AD13: =DEC2HEX(MOD(I13,256),2) -> 5F | AE13: =DEC2HEX(J13/256,2) -> 00 | AF13: =DEC2HEX(MOD(J13,256),2) -> 55 | AG13: =DEC2HEX(K13,2) -> 0A | AH13: =DEC2HEX(L13/256,2) -> 00 | AI13: =DEC2HEX(MOD(L13,256),2) -> 55 | AJ13: =DEC2HEX(M13/256,2) -> 00 | AK13: =DEC2HEX(MOD(M13,256),2) -> 52 | AL13: =DEC2HEX(N13,2) -> 01
A14: ='2.BCMU-NVMC'!A23 -> 21 | B14: ='2.BCMU-NVMC'!B23 -> 0xF011 | C14: ='2.BCMU-NVMC'!C23 -> 环境温度过低 | D14: ='2.BCMU-NVMC'!D23 -> 2 | E14: ='2.BCMU-NVMC'!E23 -> 5 | F14: ='2.BCMU-NVMC'!F23 -> 10 | G14: ='2.BCMU-NVMC'!G23 -> 30 | H14: ='2.BCMU-NVMC'!H23 -> 17 | ... S14: ='2.BCMU-NVMC'!S23 -> 79 | V14: =DEC2HEX(D14,2) -> 02 | W14: =DEC2HEX(E14,2) -> 05 | X14: =DEC2HEX(F14/256,2) -> 00 | Y14: =DEC2HEX(MOD(F14,256),2) -> 0A | Z14: =DEC2HEX(G14/256,2) -> 00 | AA14: =DEC2HEX(MOD(G14,256),2) -> 1E | AB14: =DEC2HEX(H14,2) -> 11 | AC14: =DEC2HEX(I14/256,2) -> 00 | AD14: =DEC2HEX(MOD(I14,256),2) -> 1E | AE14: =DEC2HEX(J14/256,2) -> 00 | AF14: =DEC2HEX(MOD(J14,256),2) -> 23 | AG14: =DEC2HEX(K14,2) -> 0B | AH14: =DEC2HEX(L14/256,2) -> 00 | AI14: =DEC2HEX(MOD(L14,256),2) -> 00 | AJ14: =DEC2HEX(M14/256,2) -> 00 | AK14: =DEC2HEX(MOD(M14,256),2) -> 00 | AL14: =DEC2HEX(N14,2) -> 00
A15: ='2.BCMU-NVMC'!A20 -> 18 | B15: ='2.BCMU-NVMC'!B20 -> 0xF012 | C15: ='2.BCMU-NVMC'!C20 -> 供电电压过高 | D15: ='2.BCMU-NVMC'!D20 -> 1 | E15: ='2.BCMU-NVMC'!E20 -> 3 | F15: ='2.BCMU-NVMC'!F20 -> 320 | G15: ='2.BCMU-NVMC'!G20 -> 260 | H15: ='2.BCMU-NVMC'!H20 -> 17 | ... S15: ='2.BCMU-NVMC'!S20 -> 68 | V15: =DEC2HEX(D15,2) -> 01 | W15: =DEC2HEX(E15,2) -> 03 | X15: =DEC2HEX(F15/256,2) -> 01 | Y15: =DEC2HEX(MOD(F15,256),2) -> 40 | Z15: =DEC2HEX(G15/256,2) -> 01 | AA15: =DEC2HEX(MOD(G15,256),2) -> 04 | AB15: =DEC2HEX(H15,2) -> 11 | AC15: =DEC2HEX(I15/256,2) -> 01 | AD15: =DEC2HEX(MOD(I15,256),2) -> F4 | AE15: =DEC2HEX(J15/256,2) -> 01 | AF15: =DEC2HEX(MOD(J15,256),2) -> F4 | AG15: =DEC2HEX(K15,2) -> 00 | AH15: =DEC2HEX(L15/256,2) -> 01 | AI15: =DEC2HEX(MOD(L15,256),2) -> F4 | AJ15: =DEC2HEX(M15/256,2) -> 01 | AK15: =DEC2HEX(MOD(M15,256),2) -> F4 | AL15: =DEC2HEX(N15,2) -> 00
A16: ='2.BCMU-NVMC'!A21 -> 19 | B16: ='2.BCMU-NVMC'!B21 -> 0xF013 | C16: ='2.BCMU-NVMC'!C21 -> 供电电压过低 | D16: ='2.BCMU-NVMC'!D21 -> 1 | E16: ='2.BCMU-NVMC'!E21 -> 3 | F16: ='2.BCMU-NVMC'!F21 -> 90 | G16: ='2.BCMU-NVMC'!G21 -> 120 | H16: ='2.BCMU-NVMC'!H21 -> 17 | ... S16: ='2.BCMU-NVMC'!S21 -> 71 | V16: =DEC2HEX(D16,2) -> 01 | W16: =DEC2HEX(E16,2) -> 03 | X16: =DEC2HEX(F16/256,2) -> 00 | Y16: =DEC2HEX(MOD(F16,256),2) -> 5A | Z16: =DEC2HEX(G16/256,2) -> 00 | AA16: =DEC2HEX(MOD(G16,256),2) -> 78 | AB16: =DEC2HEX(H16,2) -> 11 | AC16: =DEC2HEX(I16/256,2) -> 00 | AD16: =DEC2HEX(MOD(I16,256),2) -> 00 | AE16: =DEC2HEX(J16/256,2) -> 00 | AF16: =DEC2HEX(MOD(J16,256),2) -> 00 | AG16: =DEC2HEX(K16,2) -> 00 | AH16: =DEC2HEX(L16/256,2) -> 00 | AI16: =DEC2HEX(MOD(L16,256),2) -> 00 | AJ16: =DEC2HEX(M16/256,2) -> 00 | AK16: =DEC2HEX(MOD(M16,256),2) -> 00 | AL16: =DEC2HEX(N16,2) -> 00
A17: ='2.BCMU-NVMC'!A12 -> 10 | B17: ='2.BCMU-NVMC'!B12 -> 0xF014 | C17: ='2.BCMU-NVMC'!C12 -> 高压绝缘故障 | D17: ='2.BCMU-NVMC'!D12 -> 3 | E17: ='2.BCMU-NVMC'!E12 -> 20 | F17: ='2.BCMU-NVMC'!F12 -> 600 | G17: ='2.BCMU-NVMC'!G12 -> 800 | H17: ='2.BCMU-NVMC'!H12 -> 17 | ... S17: ='2.BCMU-NVMC'!S12 -> 30 | V17: =DEC2HEX(D17,2) -> 03 | W17: =DEC2HEX(E17,2) -> 14 | X17: =DEC2HEX(F17/256,2) -> 02 | Y17: =DEC2HEX(MOD(F17,256),2) -> 58 | Z17: =DEC2HEX(G17/256,2) -> 03 | AA17: =DEC2HEX(MOD(G17,256),2) -> 20 | AB17: =DEC2HEX(H17,2) -> 11 | AC17: =DEC2HEX(I17/256,2) -> 03 | AD17: =DEC2HEX(MOD(I17,256),2) -> 20 | AE17: =DEC2HEX(J17/256,2) -> 03 | AF17: =DEC2HEX(MOD(J17,256),2) -> E8 | AG17: =DEC2HEX(K17,2) -> 0B | AH17: =DEC2HEX(L17/256,2) -> 03 | AI17: =DEC2HEX(MOD(L17,256),2) -> E8 | AJ17: =DEC2HEX(M17/256,2) -> 04 | AK17: =DEC2HEX(MOD(M17,256),2) -> B0 | AL17: =DEC2HEX(N17,2) -> 01
A18: ='2.BCMU-NVMC'!A24 -> 22 | B18: ='2.BCMU-NVMC'!B24 -> 0xF019 | C18: ='2.BCMU-NVMC'!C24 -> S板过高温(单体) | D18: ='2.BCMU-NVMC'!D24 -> 1 | E18: ='2.BCMU-NVMC'!E24 -> 5 | F18: ='2.BCMU-NVMC'!F24 -> 105 | G18: ='2.BCMU-NVMC'!G24 -> 0 | H18: ='2.BCMU-NVMC'!H24 -> 17 | ... S18: ='2.BCMU-NVMC'!S24 -> 91 | V18: =DEC2HEX(D18,2) -> 01 | W18: =DEC2HEX(E18,2) -> 05 | X18: =DEC2HEX(F18/256,2) -> 00 | Y18: =DEC2HEX(MOD(F18,256),2) -> 69 | Z18: =DEC2HEX(G18/256,2) -> 00 | AA18: =DEC2HEX(MOD(G18,256),2) -> 00 | AB18: =DEC2HEX(H18,2) -> 11 | AC18: =DEC2HEX(I18/256,2) -> 00 | AD18: =DEC2HEX(MOD(I18,256),2) -> 00 | AE18: =DEC2HEX(J18/256,2) -> 00 | AF18: =DEC2HEX(MOD(J18,256),2) -> 00 | AG18: =DEC2HEX(K18,2) -> 00 | AH18: =DEC2HEX(L18/256,2) -> 00 | AI18: =DEC2HEX(MOD(L18,256),2) -> 00 | AJ18: =DEC2HEX(M18/256,2) -> 00 | AK18: =DEC2HEX(MOD(M18,256),2) -> 00 | AL18: =DEC2HEX(N18,2) -> 00
A19: ='2.BCMU-NVMC'!A25 -> 23 | B19: ='2.BCMU-NVMC'!B25 -> 0xF01A | C19: ='2.BCMU-NVMC'!C25 -> S板过高温(环境) | D19: ='2.BCMU-NVMC'!D25 -> 1 | E19: ='2.BCMU-NVMC'!E25 -> 5 | F19: ='2.BCMU-NVMC'!F25 -> 105 | G19: ='2.BCMU-NVMC'!G25 -> 0 | H19: ='2.BCMU-NVMC'!H25 -> 17 | ... S19: ='2.BCMU-NVMC'!S25 -> 92 | V19: =DEC2HEX(D19,2) -> 01 | W19: =DEC2HEX(E19,2) -> 05 | X19: =DEC2HEX(F19/256,2) -> 00 | Y19: =DEC2HEX(MOD(F19,256),2) -> 69 | Z19: =DEC2HEX(G19/256,2) -> 00 | AA19: =DEC2HEX(MOD(G19,256),2) -> 00 | AB19: =DEC2HEX(H19,2) -> 11 | AC19: =DEC2HEX(I19/256,2) -> 00 | AD19: =DEC2HEX(MOD(I19,256),2) -> 00 | AE19: =DEC2HEX(J19/256,2) -> 00 | AF19: =DEC2HEX(MOD(J19,256),2) -> 00 | AG19: =DEC2HEX(K19,2) -> 00 | AH19: =DEC2HEX(L19/256,2) -> 00 | AI19: =DEC2HEX(MOD(L19,256),2) -> 00 | AJ19: =DEC2HEX(M19/256,2) -> 00 | AK19: =DEC2HEX(MOD(M19,256),2) -> 00 | AL19: =DEC2HEX(N19,2) -> 00
A20: ='2.BCMU-NVMC'!A26 -> 24 | B20: ='2.BCMU-NVMC'!B26 -> 0xF01B | C20: ='2.BCMU-NVMC'!C26 -> S板充电插座过温 | D20: ='2.BCMU-NVMC'!D26 -> 3 | E20: ='2.BCMU-NVMC'!E26 -> 3 | F20: ='2.BCMU-NVMC'!F26 -> 200 | G20: ='2.BCMU-NVMC'!G26 -> 200 | H20: ='2.BCMU-NVMC'!H26 -> 0 | ... S20: ='2.BCMU-NVMC'!S26 -> 0 | V20: =DEC2HEX(D20,2) -> 03 | W20: =DEC2HEX(E20,2) -> 03 | X20: =DEC2HEX(F20/256,2) -> 00 | Y20: =DEC2HEX(MOD(F20,256),2) -> C8 | Z20: =DEC2HEX(G20/256,2) -> 00 | AA20: =DEC2HEX(MOD(G20,256),2) -> C8 | AB20: =DEC2HEX(H20,2) -> 00 | AC20: =DEC2HEX(I20/256,2) -> 00 | AD20: =DEC2HEX(MOD(I20,256),2) -> 8C | AE20: =DEC2HEX(J20/256,2) -> 00 | AF20: =DEC2HEX(MOD(J20,256),2) -> 00 | AG20: =DEC2HEX(K20,2) -> 11 | AH20: =DEC2HEX(L20/256,2) -> 00 | AI20: =DEC2HEX(MOD(L20,256),2) -> 87 | AJ20: =DEC2HEX(M20/256,2) -> 00 | AK20: =DEC2HEX(MOD(M20,256),2) -> 82 | AL20: =DEC2HEX(N20,2) -> 0A
A21: ='2.BCMU-NVMC'!A27 -> 25 | B21: ='2.BCMU-NVMC'!B27 -> 0xF01C | C21: ='2.BCMU-NVMC'!C27 -> 环流过大 | D21: ='2.BCMU-NVMC'!D27 -> 1 | E21: ='2.BCMU-NVMC'!E27 -> 3 | F21: ='2.BCMU-NVMC'!F27 -> 100 | G21: ='2.BCMU-NVMC'!G27 -> 0 | H21: ='2.BCMU-NVMC'!H27 -> 17 | ... S21: ='2.BCMU-NVMC'!S27 -> 96 | V21: =DEC2HEX(D21,2) -> 01 | W21: =DEC2HEX(E21,2) -> 03 | X21: =DEC2HEX(F21/256,2) -> 00 | Y21: =DEC2HEX(MOD(F21,256),2) -> 64 | Z21: =DEC2HEX(G21/256,2) -> 00 | AA21: =DEC2HEX(MOD(G21,256),2) -> 00 | AB21: =DEC2HEX(H21,2) -> 11 | AC21: =DEC2HEX(I21/256,2) -> 00 | AD21: =DEC2HEX(MOD(I21,256),2) -> 00 | AE21: =DEC2HEX(J21/256,2) -> 00 | AF21: =DEC2HEX(MOD(J21,256),2) -> 00 | AG21: =DEC2HEX(K21,2) -> 00 | AH21: =DEC2HEX(L21/256,2) -> 00 | AI21: =DEC2HEX(MOD(L21,256),2) -> 00 | AJ21: =DEC2HEX(M21/256,2) -> 00 | AK21: =DEC2HEX(MOD(M21,256),2) -> 00 | AL21: =DEC2HEX(N21,2) -> 00
A22: ='2.BCMU-NVMC'!A6 -> 4 | B22: ='2.BCMU-NVMC'!B6 -> 0xF01E | C22: ='2.BCMU-NVMC'!C6 -> 模块总压过高 | D22: ='2.BCMU-NVMC'!D6 -> 3 | E22: ='2.BCMU-NVMC'!E6 -> 2 | F22: ='2.BCMU-NVMC'!F6 -> 639 | G22: ='2.BCMU-NVMC'!G6 -> 0 | H22: ='2.BCMU-NVMC'!H6 -> 17 | ... S22: ='2.BCMU-NVMC'!S6 -> 12 | V22: =DEC2HEX(D22,2) -> 03 | W22: =DEC2HEX(E22,2) -> 02 | X22: =DEC2HEX(F22/256,2) -> 02 | Y22: =DEC2HEX(MOD(F22,256),2) -> 7F | Z22: =DEC2HEX(G22/256,2) -> 00 | AA22: =DEC2HEX(MOD(G22,256),2) -> 00 | AB22: =DEC2HEX(H22,2) -> 11 | AC22: =DEC2HEX(I22/256,2) -> 02 | AD22: =DEC2HEX(MOD(I22,256),2) -> 76 | AE22: =DEC2HEX(J22/256,2) -> 02 | AF22: =DEC2HEX(MOD(J22,256),2) -> 6D | AG22: =DEC2HEX(K22,2) -> 10 | AH22: =DEC2HEX(L22/256,2) -> 02 | AI22: =DEC2HEX(MOD(L22,256),2) -> 6D | AJ22: =DEC2HEX(M22/256,2) -> 02 | AK22: =DEC2HEX(MOD(M22,256),2) -> 6D | AL22: =DEC2HEX(N22,2) -> 10
A23: ='2.BCMU-NVMC'!A7 -> 5 | B23: ='2.BCMU-NVMC'!B7 -> 0xF01F | C23: ='2.BCMU-NVMC'!C7 -> 模块总压过低 | D23: ='2.BCMU-NVMC'!D7 -> 3 | E23: ='2.BCMU-NVMC'!E7 -> 2 | F23: ='2.BCMU-NVMC'!F7 -> 513 | G23: ='2.BCMU-NVMC'!G7 -> 810 | H23: ='2.BCMU-NVMC'!H7 -> 14 | ... S23: ='2.BCMU-NVMC'!S7 -> 15 | V23: =DEC2HEX(D23,2) -> 03 | W23: =DEC2HEX(E23,2) -> 02 | X23: =DEC2HEX(F23/256,2) -> 02 | Y23: =DEC2HEX(MOD(F23,256),2) -> 01 | Z23: =DEC2HEX(G23/256,2) -> 03 | AA23: =DEC2HEX(MOD(G23,256),2) -> 2A | AB23: =DEC2HEX(H23,2) -> 0E | AC23: =DEC2HEX(I23/256,2) -> 02 | AD23: =DEC2HEX(MOD(I23,256),2) -> 0A | AE23: =DEC2HEX(J23/256,2) -> 02 | AF23: =DEC2HEX(MOD(J23,256),2) -> 13 | AG23: =DEC2HEX(K23,2) -> 0E | AH23: =DEC2HEX(L23/256,2) -> 02 | AI23: =DEC2HEX(MOD(L23,256),2) -> 13 | AJ23: =DEC2HEX(M23/256,2) -> 02 | AK23: =DEC2HEX(MOD(M23,256),2) -> 1C | AL23: =DEC2HEX(N23,2) -> 09
A24: ='2.BCMU-NVMC'!A13 -> 11 | B24: ='2.BCMU-NVMC'!B13 -> 0xF020 | C24: ='2.BCMU-NVMC'!C13 -> 充电温度高 | D24: ='2.BCMU-NVMC'!D13 -> 3 | E24: ='2.BCMU-NVMC'!E13 -> 5 | F24: ='2.BCMU-NVMC'!F13 -> 100 | G24: ='2.BCMU-NVMC'!G13 -> 0 | H24: ='2.BCMU-NVMC'!H13 -> 17 | ... S24: ='2.BCMU-NVMC'!S13 -> 33 | V24: =DEC2HEX(D24,2) -> 03 | W24: =DEC2HEX(E24,2) -> 05 | X24: =DEC2HEX(F24/256,2) -> 00 | Y24: =DEC2HEX(MOD(F24,256),2) -> 64 | Z24: =DEC2HEX(G24/256,2) -> 00 | AA24: =DEC2HEX(MOD(G24,256),2) -> 00 | AB24: =DEC2HEX(H24,2) -> 11 | AC24: =DEC2HEX(I24/256,2) -> 00 | AD24: =DEC2HEX(MOD(I24,256),2) -> 5F | AE24: =DEC2HEX(J24/256,2) -> 00 | AF24: =DEC2HEX(MOD(J24,256),2) -> 5A | AG24: =DEC2HEX(K24,2) -> 0B | AH24: =DEC2HEX(L24/256,2) -> 00 | AI24: =DEC2HEX(MOD(L24,256),2) -> 5A | AJ24: =DEC2HEX(M24/256,2) -> 00 | AK24: =DEC2HEX(MOD(M24,256),2) -> 55 | AL24: =DEC2HEX(N24,2) -> 01
A25: ='2.BCMU-NVMC'!A14 -> 12 | B25: ='2.BCMU-NVMC'!B14 -> 0xF021 | C25: ='2.BCMU-NVMC'!C14 -> 充电温度低 | D25: ='2.BCMU-NVMC'!D14 -> 3 | E25: ='2.BCMU-NVMC'!E14 -> 5 | F25: ='2.BCMU-NVMC'!F14 -> 42 | G25: ='2.BCMU-NVMC'!G14 -> 100 | H25: ='2.BCMU-NVMC'!H14 -> 16 | ... S25: ='2.BCMU-NVMC'!S14 -> 36 | V25: =DEC2HEX(D25,2) -> 03 | W25: =DEC2HEX(E25,2) -> 05 | X25: =DEC2HEX(F25/256,2) -> 00 | Y25: =DEC2HEX(MOD(F25,256),2) -> 2A | Z25: =DEC2HEX(G25/256,2) -> 00 | AA25: =DEC2HEX(MOD(G25,256),2) -> 64 | AB25: =DEC2HEX(H25,2) -> 10 | AC25: =DEC2HEX(I25/256,2) -> 00 | AD25: =DEC2HEX(MOD(I25,256),2) -> 2C | AE25: =DEC2HEX(J25/256,2) -> 00 | AF25: =DEC2HEX(MOD(J25,256),2) -> 2E | AG25: =DEC2HEX(K25,2) -> 0B | AH25: =DEC2HEX(L25/256,2) -> 00 | AI25: =DEC2HEX(MOD(L25,256),2) -> 2E | AJ25: =DEC2HEX(M25/256,2) -> 00 | AK25: =DEC2HEX(MOD(M25,256),2) -> 30 | AL25: =DEC2HEX(N25,2) -> 0A
A26: ='2.BCMU-NVMC'!A18 -> 16 | B26: ='2.BCMU-NVMC'!B18 -> 0xF023 | C26: ='2.BCMU-NVMC'!C18 -> SOC过低 | D26: ='2.BCMU-NVMC'!D18 -> 3 | E26: ='2.BCMU-NVMC'!E18 -> 3 | F26: ='2.BCMU-NVMC'!F18 -> 0 | G26: ='2.BCMU-NVMC'!G18 -> 5 | H26: ='2.BCMU-NVMC'!H18 -> 1 | ... S26: ='2.BCMU-NVMC'!S18 -> 51 | V26: =DEC2HEX(D26,2) -> 03 | W26: =DEC2HEX(E26,2) -> 03 | X26: =DEC2HEX(F26/256,2) -> 00 | Y26: =DEC2HEX(MOD(F26,256),2) -> 00 | Z26: =DEC2HEX(G26/256,2) -> 00 | AA26: =DEC2HEX(MOD(G26,256),2) -> 05 | AB26: =DEC2HEX(H26,2) -> 01 | AC26: =DEC2HEX(I26/256,2) -> 00 | AD26: =DEC2HEX(MOD(I26,256),2) -> 0A | AE26: =DEC2HEX(J26/256,2) -> 00 | AF26: =DEC2HEX(MOD(J26,256),2) -> 0A | AG26: =DEC2HEX(K26,2) -> 01 | AH26: =DEC2HEX(L26/256,2) -> 00 | AI26: =DEC2HEX(MOD(L26,256),2) -> 14 | AJ26: =DEC2HEX(M26/256,2) -> 00 | AK26: =DEC2HEX(MOD(M26,256),2) -> 14 | AL26: =DEC2HEX(N26,2) -> 01
A27: ='2.BCMU-NVMC'!A19 -> 17 | B27: ='2.BCMU-NVMC'!B19 -> 0xF024 | C27: ='2.BCMU-NVMC'!C19 -> SOH过低 | D27: ='2.BCMU-NVMC'!D19 -> 3 | E27: ='2.BCMU-NVMC'!E19 -> 3 | F27: ='2.BCMU-NVMC'!F19 -> 0 | G27: ='2.BCMU-NVMC'!G19 -> 0 | H27: ='2.BCMU-NVMC'!H19 -> 0 | ... S27: ='2.BCMU-NVMC'!S19 -> 54 | V27: =DEC2HEX(D27,2) -> 03 | W27: =DEC2HEX(E27,2) -> 03 | X27: =DEC2HEX(F27/256,2) -> 00 | Y27: =DEC2HEX(MOD(F27,256),2) -> 00 | Z27: =DEC2HEX(G27/256,2) -> 00 | AA27: =DEC2HEX(MOD(G27,256),2) -> 00 | AB27: =DEC2HEX(H27,2) -> 00 | AC27: =DEC2HEX(I27/256,2) -> 00 | AD27: =DEC2HEX(MOD(I27,256),2) -> 00 | AE27: =DEC2HEX(J27/256,2) -> 00 | AF27: =DEC2HEX(MOD(J27,256),2) -> 00 | AG27: =DEC2HEX(K27,2) -> 00 | AH27: =DEC2HEX(L27/256,2) -> 00 | AI27: =DEC2HEX(MOD(L27,256),2) -> 46 | AJ27: =DEC2HEX(M27/256,2) -> 00 | AK27: =DEC2HEX(MOD(M27,256),2) -> 65 | AL27: =DEC2HEX(N27,2) -> 01
A28: 手动写 | B28: 自动算 | C28: 十进制
A30: =A3 -> 1 | B30: =B3 -> 0xF001 | C30: ="[0x"&_xlfn.TEXTJOIN(",0x",TRUE,V3:AL3)&"]" -> [0x03,0x02,0x0D,0xDE,0x00,0x00,0x11,0x0D,0xAC,0x0D,0x7F,0x10,0x0D,0x7F,0x0D,0x7A,0x10]
A31: =A4 -> 2 | B31: =B4 -> 0xF002 | C31: ="[0x"&_xlfn.TEXTJOIN(",0x",TRUE,V4:AL4)&"]" -> [0x03,0x02,0x0B,0x22,0x11,0x94,0x0E,0x0B,0x54,0x0B,0x86,0x09,0x0B,0x86,0x0B,0xB8,0x09]
A32: =A5 -> 3 | B32: =B5 -> 0xF003 | C32: ="[0x"&_xlfn.TEXTJOIN(",0x",TRUE,V5:AL5)&"]" -> [0x03,0x05,0x00,0xFA,0x00,0x00,0x11,0x00,0xC8,0x00,0xC3,0x0B,0x00,0x96,0x00,0x91,0x01]
A33: =A6 -> 13 | B33: =B6 -> 0xF006 | C33: ="[0x"&_xlfn.TEXTJOIN(",0x",TRUE,V6:AL6)&"]" -> [0x03,0x05,0x00,0x64,0x00,0x00,0x11,0x00,0x5F,0x00,0x5A,0x0B,0x00,0x5A,0x00,0x55,0x01]
A34: =A7 -> 14 | B34: =B7 -> 0xF007 | C34: ="[0x"&_xlfn.TEXTJOIN(",0x",TRUE,V7:AL7)&"]" -> [0x03,0x05,0x00,0x0A,0x00,0x64,0x11,0x00,0x1C,0x00,0x1E,0x0B,0x00,0x1E,0x00,0x20,0x09]
A35: =A8 -> 15 | B35: =B8 -> 0xF008 | C35: ="[0x"&_xlfn.TEXTJOIN(",0x",TRUE,V8:AL8)&"]" -> [0x03,0x0A,0x00,0x37,0x00,0x00,0x11,0x00,0x32,0x00,0x31,0x01,0x00,0x30,0x00,0x2F,0x01]
A36: =A9 -> 6 | B36: =B9 -> 0xF00B | C36: ="[0x"&_xlfn.TEXTJOIN(",0x",TRUE,V9:AL9)&"]" -> [0x03,0x02,0x02,0x7F,0x00,0x00,0x11,0x02,0x76,0x02,0x6D,0x10,0x02,0x6D,0x02,0x6D,0x10]
A37: =A10 -> 7 | B37: =B10 -> 0xF00C | C37: ="[0x"&_xlfn.TEXTJOIN(",0x",TRUE,V10:AL10)&"]" -> [0x03,0x02,0x02,0x01,0x03,0x2A,0x0E,0x02,0x0A,0x02,0x13,0x0E,0x02,0x13,0x02,0x1C,0x09]
A38: =A11 -> 8 | B38: =B11 -> 0xF00E | C38: ="[0x"&_xlfn.TEXTJOIN(",0x",TRUE,V11:AL11)&"]" -> [0x03,0x05,0x75,0xC6,0x75,0x30,0x11,0x75,0x94,0x75,0x30,0x09,0x75,0x62,0x75,0x30,0x01]
A39: =A12 -> 9 | B39: =B12 -> 0xF00F | C39: ="[0x"&_xlfn.TEXTJOIN(",0x",TRUE,V12:AL12)&"]" -> [0x03,0x05,0x75,0xC6,0x75,0x30,0x11,0x75,0x94,0x75,0x30,0x0A,0x75,0x62,0x75,0x30,0x01]
A40: =A13 -> 20 | B40: =B13 -> 0xF010 | C40: ="[0x"&_xlfn.TEXTJOIN(",0x",TRUE,V13:AL13)&"]" -> [0x02,0x05,0x00,0x64,0x00,0x00,0x11,0x00,0x5F,0x00,0x55,0x0A,0x00,0x55,0x00,0x52,0x01]
A41: =A14 -> 21 | B41: =B14 -> 0xF011 | C41: ="[0x"&_xlfn.TEXTJOIN(",0x",TRUE,V14:AL14)&"]" -> [0x02,0x05,0x00,0x0A,0x00,0x1E,0x11,0x00,0x1E,0x00,0x23,0x0B,0x00,0x00,0x00,0x00,0x00]
...

Sheet 2.BCMU告警等级
E1: Byt0 | F1: Byt1 | G1: Byt2
B2: 系统主故障等级 | C2: 内部故障等级 | D2: PID | E2: 切断使能 | F2: 充电功率降级/% | G2: 放电功率降级/%
B3: 1级（轻微） | C3: 1 | D3: 0xFF01 | E3: 0 | F3: 100 | G3: 100
C4: 2 | D4: 0xFF02 | E4: 0 | F4: 100 | G4: 100
C5: 3 | D5: 0xFF03 | E5: 0 | F5: 100 | G5: 100
C6: 4 | D6: 0xFF04 | E6: 0 | F6: 100 | G6: 100
C7: 5 | D7: 0xFF05 | E7: 0 | F7: 100 | G7: 100
C8: 6 | D8: 0xFF06 | E8: 0 | F8: 80 | G8: 100
B9: 2级（一般） | C9: 7 | D9: 0xFF07 | E9: 0 | F9: 60 | G9: 100
C10: 8 | D10: 0xFF08 | E10: 0 | F10: 100 | G10: 80
C11: 9 | D11: 0xFF09 | E11: 0 | F11: 100 | G11: 50
C12: 10 | D12: 0xFF0A | E12: 0 | F12: 50 | G12: 100
C13: 11 | D13: 0xFF0B | E13: 0 | F13: 50 | G13: 50
C14: 12 | D14: 0xFF0C | E14: 0 | F14: 0 | G14: 50
B15: 3级（严重） | C15: 13 | D15: 0xFF0D | E15: 1 | F15: 50 | G15: 20
C16: 14 | D16: 0xFF0E | E16: 2 | F16: 50 | G16: 0
C17: 15 | D17: 0xFF0F | E17: 3 | F17: 0 | G17: 0
C18: 16 | D18: 0xFF10 | E18: 4 | F18: 0 | G18: 0
C19: 17 | D19: 0xFF11 | E19: 5 | F19: 0 | G19: 0
C20: 18 | D20: TBD

Sheet Sheet2
A2: NVMC模块有36个F0XX的故障阈值PID，表里面只有25个，多的是什么
A3: 内部故障等级在哪里查
A4: 簇放电/充电过流用乘系数和加常数的时候是不是配置表和故障模块都要重设
A5: 阈值设置模式是什么意思 0x0: Program Setting 0x1: Manual Setting
A6: RTE_CAN_CanDataPduId函数是空的，没有描述，是正常的吗 模型里面空的可以，生成代码的时候只引用，工程里面的是写了的
A7: 51-SOC过低3级 没有故障等级
A8: 环流过大的故障如何用数值体现
A9: 过高时T>触发阈值，恢复时T<恢复阈值，若不准恢复，设置恢复阈值为0，T无法<0。若过低时，T<触发阈值，恢复时T>恢复阈值，T肯定能>0。推断出0不是代表物理值，而是逻辑值。需要查模型
A10: 均衡配置参数不同电芯也用的同样的数值，应该怎么去设置
